#VRML_SIM R2025a utf8

WorldInfo {
  basicTimeStep 16
}
Viewpoint {
  orientation -0.027663656944698647 0.14041118570132766 0.9897067348535086 2.3508050259315505
  position 6.096532959953102 -4.835342106968298 1.4096301000640394
  description "Vista principal"
}
TexturedBackground {
}
TexturedBackgroundLight {
}
DirectionalLight {
  color 1 1 0.95
  direction -0.3 -1 -0.4
  intensity 0.9
}
Floor {
}
Robot {
  translation 0 0.05 0
  rotation 0 1 0 0
  children [
    Solid {
      translation 0 0 -3.923996155634091e-06
      children [
        Shape {
          appearance PBRAppearance {
            baseColor 0.1 0.6 0.8
            roughness 0.3
          }
          geometry Box {
            size 0.3 0.05 0.2
          }
        }
      ]
      physics Physics {
        mass 0.5
      }
      linearVelocity 0 0 -6.007405773239843e-11
    }
    HingeJoint {
      jointParameters HingeJointParameters {
        position 0.057935645561949536
        anchor 0 0.05 0.1
      }
      endPoint Solid {
        translation 0 -0.24949665995967035 0.082629027862505
        rotation 1 0 0 0.057935645561949536
        children [
          Shape {
            appearance PBRAppearance {
              baseColor 1 0.8 0
              roughness 0.3
            }
            geometry Capsule {
              height 0.5
              radius 0.02
            }
          }
        ]
        physics Physics {
          mass 0.1
        }
        linearVelocity 0 -0.0032922484512783283 0.055725807290524475
        angularVelocity -0.18606964109429217 0 0
      }
    }
  ]
  controller "pendulo_controller"
}
